Workbook

Sheet Project_Brief
B2: HEALTH DATA ANALYSIS
B4: Exploring Child Low Income and School Readiness Across English Local Authorities
B6: BACKGROUND
B8: Child poverty and early childhood development are important wider determinants of health, as the conditions in which children grow can influence their development and future health and wellbeing. This project focuses on two indicators from the Office for Health Improvement and Disparities (OHID) Public Health Outcomes Framework: children in absolute low-income families under 16 and school readiness, measured by the percentage of children achieving a good level of development at the end of Reception. The analysis will examine changes in child low income in Cheshire West and Chester compared with England, compare local-authority outcomes, and explore whether an observable association exists between child low income and school readiness across English local authorities. The analysis is exploratory and considers area-level patterns; it does not assume that one indicator causes changes in the other.
B13: INDICATOR FRAMEWORK
B15: INDICATOR | E15: SOURCE
B16: Children in absolute low-income families (under 16s) B01b | E16: OHID Public Health Outcomes Framework
B18: School readiness: percentage of children achieving a good level of development at the end of Reception B02a | E18: OHID Public Health Outcomes Framework
B21: GEOGRAPHICAL FOCUS
B23: England - local authorities
B24: Primary focus
B25: Cheshire West and Chester
B26: National benchmark
B27: England
B29: ANALYSIS
B31: TREND ANALYSIS
B32: 0.1
B33: How has the proportion of children in absolute low-income families changed in Cheshire West and Chester compared with England between 2021/22 to 2024/25?
B35: GEOGRAPHICAL COMPARISON
B36: 0.2
B37: How does Cheshire West and Chester compare with selected English local authorities on child low income and school readiness in 2024/25?
B39: RELATIONSHIP ANALYSIS
B40: 0.3
B41: Is there an observable association between child low income and the proportion of children with free school meal status achieving a good level of development at the end of Reception across English local authorities in 2024/25?

Sheet Analysis_sheet
B2: Question 1: How has the proportion of children in absolute low-income families changed in Cheshire West and Chester compared with England between 2021/22 to 2024/25?
B6: Year | C6: Cheshire West & Chester (%) | D6: England (%) | E6: CW&C Year-on-Year Change (pp) | F6: CW&C Gap vs England (pp) | G6: CW&C vs England (pp)
B7: 2021/22 | C7: =C_cheshire_vs_England_B01b!G3 -> 15.6 | D7: =C_cheshire_vs_England_B01b!G2 -> 19.7 | G7: =C7-D7 -> -4.1
B8: 2022/23 | C8: =C_cheshire_vs_England_B01b!G5 -> 17.8 | D8: =C_cheshire_vs_England_B01b!G4 -> 21.9 | E8: =C8-C7 -> 2.2 | F8: =D8-D7 -> 2.2 | G8: =C8-D8 -> -4.1
B9: 2023/24 | C9: =C_cheshire_vs_England_B01b!G7 -> 16.7 | D9: =C_cheshire_vs_England_B01b!G6 -> 21.1 | E9: =C9-C8 -> -1.1 | F9: =D9-D8 -> -0.8 | G9: =C9-D9 -> -4.4
B10: 2024/25 | C10: =C_cheshire_vs_England_B01b!G9 -> 15.1 | D10: =C_cheshire_vs_England_B01b!G8 -> 19.8 | E10: =C10-C9 -> -1.6 | F10: =D10-D9 -> -1.3 | G10: =C10-D10 -> -4.7
B28: Key finding: Child low-income rates in Cheshire West and Chester increased between 2021/22 and 2022/23 before declining in the following two years. The rate remained below the England benchmark throughout the period.
B32: Question 2: How does Cheshire West and Chester compare with selected English local authorities on child low income and school readiness in 2024/25?
B36: Local Authorities | C36: Children in absolute low income families Value | K36: Local Authorities | L36: School readiness_Value
B37: Barnet | C37: 11.2 | E37: MEDIAN | F37: MEAN | K37: Barking and Dagenham | L37: 55.6845
B38: Bath and North East Somerset | C38: 10.2 | E38: =MEDIAN(C37:C191) -> 21.8 | F38: =SUM(C37:C191)/COUNT(C37:C191) -> 42.721739 | K38: Barnet | L38: 55
B39: Birmingham | C39: 39.5 | K39: Barnsley | L39: 55.9748
B40: Central Bedfordshire | C40: 11.7 | K40: Bath and North East Somerset | L40: 38.2199
B41: Cheshire East | C41: 13 | K41: Bedford | L41: 47.4522
B42: Cheshire West and Chester | C42: 15.1 | K42: Bexley | L42: 56.9014
B43: Croydon | C43: 16.4 | K43: Birmingham | L43: 59.4811
B44: Darlington | C44: 24.8 | K44: Blackburn with Darwen | L44: 49.5208
B45: England | C45: 19.8 | K45: Blackpool | L45: 52.3002
B46: Kent | C46: 15.3 | K46: Bolton | L46: 51.7045
B47: Liverpool | C47: 29.6 | K47: Bournemouth, Christchurch and Poole | L47: 53.8293
B48: Manchester | C48: 35.5 | K48: Bracknell Forest | L48: 43.2432
B49: Nottingham | C49: 33.7 | K49: Bradford | L49: 50.3515
B50: Nottinghamshire | C50: 19.5 | K50: Brent | L50: 61.284
... B59: Grand Total | C59: 491.3 | K59: Central Bedfordshire | L59: 43.4457
K60: Cheshire East | L60: 42.638
K61: Cheshire West and Chester | L61: 45.045
K62: City of London | L62: 100
K63: Cornwall | L63: 51.5021
K64: County Durham | L64: 46.0108
K65: Coventry | L65: 50.5405
K66: Croydon | L66: 60.2163
K67: Cumberland | L67: 45.3826
K68: Darlington | L68: 44.7489
K69: Derby | L69: 52.0681
K70: Derbyshire | L70: 47.0968
K71: Devon | L71: 46.3115
... K96: Isle of Wight | L96: 53.5433
K97: Isles of Scilly
K98: Islington | L98: 57.0093
K99: Kensington and Chelsea | L99: 55.814
...

Sheet c_cheshire_vs_england_B02a
A1: Indicator ID | B1: Indicator Name | C1: Parent Code | D1: Parent Name | E1: AreaName | F1: Area Type | G1: Sex | H1: Age | I1: Time period | J1: Value | K1: Lower CI 95.0 limit | L1: Upper CI 95.0 limit | M1: Lower CI 99.8 limit | N1: Upper CI 99.8 limit | O1: Count | P1: Denominator
A2: 90632 | B2: B02a - School readiness: percentage of children with free school meal status achieving a good level of development at the end of Reception | C2: E92000001 | D2: England | E2: England | F2: England | G2: Persons | H2: 5 yrs | I2: 2021/22 | J2: 49.1 | K2: 48.83 | L2: 49.41 | M2: 48.67 | N2: 49.58 | O2: 55944 | P2: 113882
A3: 90632 | B3: B02a - School readiness: percentage of children with free school meal status achieving a good level of development at the end of Reception | C3: E92000001 | D3: England | E3: Cheshire West and Chester | F3: Upper tier local authorities (post 4/23) | G3: Persons | H3: 5 yrs | I3: 2021/22 | J3: 43.3 | K3: 38.97 | L3: 47.8 | M3: 36.54 | N3: 50.39 | O3: 208 | P3: 480
A4: 90632 | B4: B02a - School readiness: percentage of children with free school meal status achieving a good level of development at the end of Reception | E4: England | F4: England | G4: Persons | H4: 5 yrs | I4: 2022/23 | J4: 51.55 | K4: 51.25 | L4: 51.85 | M4: 51.08 | N4: 52.02 | O4: 56242 | P4: 109100
A5: 90632 | B5: B02a - School readiness: percentage of children with free school meal status achieving a good level of development at the end of Reception | C5: E92000001 | D5: England | E5: Cheshire West and Chester | F5: Upper tier local authorities (post 4/23) | G5: Persons | H5: 5 yrs | I5: 2022/23 | J5: 48.57 | K5: 44.32 | L5: 52.84 | M5: 41.92 | N5: 55.28 | O5: 255 | P5: 525
A6: 90632 | B6: B02a - School readiness: percentage of children with free school meal status achieving a good level of development at the end of Reception | E6: England | F6: England | G6: Persons | H6: 5 yrs | I6: 2023/24 | J6: 51.5232 | K6: 51.2205 | L6: 51.8259 | M6: 51.0458 | N6: 52.0003 | O6: 53951 | P6: 104712
A7: 90632 | B7: B02a - School readiness: percentage of children with free school meal status achieving a good level of development at the end of Reception | C7: E92000001 | D7: England | E7: Cheshire West and Chester | F7: Upper tier local authorities (post 4/23) | G7: Persons | H7: 5 yrs | I7: 2023/24 | J7: 43.5449 | K7: 39.0715 | L7: 48.1258 | M7: 36.5822 | N7: 50.7717 | O7: 199 | P7: 457
A8: 90632 | B8: B02a - School readiness: percentage of children with free school meal status achieving a good level of development at the end of Reception | E8: England | F8: England | G8: Persons | H8: 5 yrs | I8: 2024/25 | J8: 51.2571 | K8: 50.9477 | L8: 51.5665 | M8: 50.7692 | N8: 51.7448 | O8: 51394 | P8: 100267
A9: 90632 | B9: B02a - School readiness: percentage of children with free school meal status achieving a good level of development at the end of Reception | C9: E92000001 | D9: England | E9: Cheshire West and Chester | F9: Upper tier local authorities (post 4/23) | G9: Persons | H9: 5 yrs | I9: 2024/25 | J9: 45.045 | K9: 40.4793 | L9: 49.6957 | M9: 37.9291 | N9: 52.3696 | O9: 200 | P9: 444

Sheet C_area_comparison_B02a
A1: Indicator ID | B1: Indicator Name | C1: Local Authorities | D1: Area Type | E1: Sex | F1: Age | G1: Time period | H1: Value | I1: Lower CI 95.0 limit | J1: Upper CI 95.0 limit | K1: Lower CI 99.8 limit | L1: Upper CI 99.8 limit | M1: Count | N1: Denominator
A2: 90632 | B2: B02a - School readiness: percentage of children with free school meal status achieving a good level of development at the end of Reception | C2: England | D2: England | E2: Persons | F2: 5 yrs | G2: 2024/25 | H2: 51.2571 | I2: 50.9477 | J2: 51.5665 | K2: 50.7692 | L2: 51.7448 | M2: 51394 | N2: 100267
A3: 90632 | B3: B02a - School readiness: percentage of children with free school meal status achieving a good level of development at the end of Reception | C3: City of London | D3: Upper tier local authorities (post 4/23) | E3: Persons | F3: 5 yrs | G3: 2024/25 | H3: 100 | I3: 56.5518 | J3: 100 | K3: 34.3654 | L3: 100 | M3: 5 | N3: 5
A4: 90632 | B4: B02a - School readiness: percentage of children with free school meal status achieving a good level of development at the end of Reception | C4: Hackney | D4: Upper tier local authorities (post 4/23) | E4: Persons | F4: 5 yrs | G4: 2024/25 | H4: 65.9058 | I4: 62.3186 | J4: 69.3197 | K4: 60.1926 | L4: 71.1916 | M4: 462 | N4: 701
A5: 90632 | B5: B02a - School readiness: percentage of children with free school meal status achieving a good level of development at the end of Reception | C5: Westminster | D5: Upper tier local authorities (post 4/23) | E5: Persons | F5: 5 yrs | G5: 2024/25 | H5: 64.3791 | I5: 58.8657 | J5: 69.536 | K5: 55.6019 | L5: 72.286 | M5: 197 | N5: 306
A6: 90632 | B6: B02a - School readiness: percentage of children with free school meal status achieving a good level of development at the end of Reception | C6: Newham | D6: Upper tier local authorities (post 4/23) | E6: Persons | F6: 5 yrs | G6: 2024/25 | H6: 64.1824 | I6: 60.994 | J6: 67.2502 | K6: 59.1155 | L6: 68.9512 | M6: 577 | N6: 899
A7: 90632 | B7: B02a - School readiness: percentage of children with free school meal status achieving a good level of development at the end of Reception | C7: Redbridge | D7: Upper tier local authorities (post 4/23) | E7: Persons | F7: 5 yrs | G7: 2024/25 | H7: 63.6364 | I7: 59.0989 | J7: 67.9435 | K7: 56.4209 | L7: 70.2863 | M7: 287 | N7: 451
A8: 90632 | B8: B02a - School readiness: percentage of children with free school meal status achieving a good level of development at the end of Reception | C8: Camden | D8: Upper tier local authorities (post 4/23) | E8: Persons | F8: 5 yrs | G8: 2024/25 | H8: 63.1455 | I8: 58.4661 | J8: 67.59 | K8: 55.7084 | L8: 70.0063 | M8: 269 | N8: 426
A9: 90632 | B9: B02a - School readiness: percentage of children with free school meal status achieving a good level of development at the end of Reception | C9: Enfield | D9: Upper tier local authorities (post 4/23) | E9: Persons | F9: 5 yrs | G9: 2024/25 | H9: 62.3318 | I9: 59.1055 | J9: 65.4524 | K9: 57.2125 | L9: 67.1899 | M9: 556 | N9: 892
A10: 90632 | B10: B02a - School readiness: percentage of children with free school meal status achieving a good level of development at the end of Reception | C10: Slough | D10: Upper tier local authorities (post 4/23) | E10: Persons | F10: 5 yrs | G10: 2024/25 | H10: 61.9808 | I10: 56.4885 | J10: 67.1827 | K10: 53.266 | L10: 69.9863 | M10: 194 | N10: 313
A11: 90632 | B11: B02a - School readiness: percentage of children with free school meal status achieving a good level of development at the end of Reception | C11: Waltham Forest | D11: Upper tier local authorities (post 4/23) | E11: Persons | F11: 5 yrs | G11: 2024/25 | H11: 61.9277 | I11: 57.1668 | J11: 66.4698 | K11: 54.3721 | L11: 68.9467 | M11: 257 | N11: 415
A12: 90632 | B12: B02a - School readiness: percentage of children with free school meal status achieving a good level of development at the end of Reception | C12: Brent | D12: Upper tier local authorities (post 4/23) | E12: Persons | F12: 5 yrs | G12: 2024/25 | H12: 61.284 | I12: 57.0042 | J12: 65.3965 | K12: 54.4964 | L12: 67.66 | M12: 315 | N12: 514
A13: 90632 | B13: B02a - School readiness: percentage of children with free school meal status achieving a good level of development at the end of Reception | C13: Greenwich | D13: Upper tier local authorities (post 4/23) | E13: Persons | F13: 5 yrs | G13: 2024/25 | H13: 61.0219 | I13: 57.3179 | J13: 64.603 | K13: 55.1497 | L13: 66.591 | M13: 418 | N13: 685
... A154: 90632 | B154: B02a - School readiness: percentage of children with free school meal status achieving a good level of development at the end of Reception | C154: Rutland | D154: Upper tier local authorities (post 4/23) | E154: Persons | F154: 5 yrs | G154: 2024/25 | H154: 33.3333 | I154: 16.2788 | J154: 56.2505 | K154: 10.7615 | L154: 67.4596 | M154: 6 | N154: 18
A155: 90632 | B155: B02a - School readiness: percentage of children with free school meal status achieving a good level of development at the end of Reception | C155: Isles of Scilly | D155: Upper tier local authorities (post 4/23) | E155: Persons | F155: 5 yrs | G155: 2024/25 | M155: 0 | N155: 0

Sheet C_area_comparison_B01b
A1: Indicator Name | B1: Parent Code | C1: AreaName | D1: Age | E1: Time period | F1: Value | G1: Lower CI 95.0 limit | H1: Upper CI 95.0 limit | I1: Count | J1: Denominator | K1: Recent Trend | L1: Compared to England value or percentiles | M1: Compared to parent value or percentiles | N1: Time period Sortable | O1: Time period range
A2: B01b - Children in absolute low income families (under 16s) | C2: England | D2: <16 yrs | E2: 2024/25 | F2: 19.8 | G2: 19.8 | H2: 19.8 | I2: 2130679 | J2: 10768248 | K2: Cannot be calculated | L2: Not compared | N2: 20240000 | O2: 1y
A3: B01b - Children in absolute low income families (under 16s) | B3: E92000001 | C3: Birmingham | D3: <16 yrs | E3: 2024/25 | F3: 39.5 | G3: 39.3 | H3: 39.8 | I3: 102507 | J3: 259195 | K3: Cannot be calculated | L3: Worse | M3: Worse | N3: 20240000 | O3: 1y
A4: B01b - Children in absolute low income families (under 16s) | B4: E92000001 | C4: Bradford | D4: <16 yrs | E4: 2024/25 | F4: 39.3 | G4: 38.9 | H4: 39.6 | I4: 49390 | J4: 125834 | K4: Cannot be calculated | L4: Worse | M4: Worse | N4: 20240000 | O4: 1y
A5: B01b - Children in absolute low income families (under 16s) | B5: E92000001 | C5: Oldham | D5: <16 yrs | E5: 2024/25 | F5: 38.2 | G5: 37.6 | H5: 38.8 | I5: 21649 | J5: 56659 | K5: Cannot be calculated | L5: Worse | M5: Worse | N5: 20240000 | O5: 1y
A6: B01b - Children in absolute low income families (under 16s) | B6: E92000001 | C6: Blackburn with Darwen | D6: <16 yrs | E6: 2024/25 | F6: 36.2 | G6: 35.5 | H6: 36.9 | I6: 13348 | J6: 36892 | K6: Cannot be calculated | L6: Worse | M6: Worse | N6: 20240000 | O6: 1y
A7: B01b - Children in absolute low income families (under 16s) | B7: E92000001 | C7: Sandwell | D7: <16 yrs | E7: 2024/25 | F7: 35.5 | G7: 35.1 | H7: 36 | I7: 27977 | J7: 78758 | K7: Cannot be calculated | L7: Worse | M7: Worse | N7: 20240000 | O7: 1y
A8: B01b - Children in absolute low income families (under 16s) | B8: E92000001 | C8: Manchester | D8: <16 yrs | E8: 2024/25 | F8: 35.5 | G8: 35.1 | H8: 35.9 | I8: 41483 | J8: 116876 | K8: Cannot be calculated | L8: Worse | M8: Worse | N8: 20240000 | O8: 1y
A9: B01b - Children in absolute low income families (under 16s) | B9: E92000001 | C9: Stoke-on-Trent | D9: <16 yrs | E9: 2024/25 | F9: 35 | G9: 34.4 | H9: 35.6 | I9: 19427 | J9: 55498 | K9: Cannot be calculated | L9: Worse | M9: Worse | N9: 20240000 | O9: 1y
A10: B01b - Children in absolute low income families (under 16s) | B10: E92000001 | C10: Leicester | D10: <16 yrs | E10: 2024/25 | F10: 34.5 | G10: 34 | H10: 35 | I10: 27709 | J10: 80340 | K10: Cannot be calculated | L10: Worse | M10: Worse | N10: 20240000 | O10: 1y
A11: B01b - Children in absolute low income families (under 16s) | B11: E92000001 | C11: Middlesbrough | D11: <16 yrs | E11: 2024/25 | F11: 34.4 | G11: 33.6 | H11: 35.1 | I11: 10911 | J11: 31762 | K11: Cannot be calculated | L11: Worse | M11: Worse | N11: 20240000 | O11: 1y
A12: B01b - Children in absolute low income families (under 16s) | B12: E92000001 | C12: Nottingham | D12: <16 yrs | E12: 2024/25 | F12: 33.7 | G12: 33.2 | H12: 34.3 | I12: 20591 | J12: 61014 | K12: Cannot be calculated | L12: Worse | M12: Worse | N12: 20240000 | O12: 1y
A13: B01b - Children in absolute low income families (under 16s) | B13: E92000001 | C13: Kingston upon Hull | D13: <16 yrs | E13: 2024/25 | F13: 33.2 | G13: 32.7 | H13: 33.8 | I13: 18403 | J13: 55396 | K13: Cannot be calculated | L13: Worse | M13: Worse | N13: 20240000 | O13: 1y
A14: B01b - Children in absolute low income families (under 16s) | B14: E92000001 | C14: Bolton | D14: <16 yrs | E14: 2024/25 | F14: 33.2 | G14: 32.7 | H14: 33.8 | I14: 22307 | J14: 67099 | K14: Cannot be calculated | L14: Worse | M14: Worse | N14: 20240000 | O14: 1y
... A155: B01b - Children in absolute low income families (under 16s) | B155: E92000001 | C155: Richmond upon Thames | D155: <16 yrs | E155: 2024/25 | F155: 5.2 | G155: 4.9 | H155: 5.5 | I155: 2015 | J155: 38935 | K155: Cannot be calculated | L155: Better | M155: Better | N155: 20240000 | O155: 1y

Sheet C_cheshire_vs_England_B01b
A1: Indicator Name | B1: AreaName | C1: Area Type | D1: Sex | E1: Age | F1: Time period | G1: Value | H1: Lower CI 95.0 limit | I1: Upper CI 95.0 limit | J1: Count | K1: Denominator | L1: Time period Sortable | M1: Time period range
A2: B01b - Children in absolute low income families (under 16s) | B2: England | C2: England | D2: Persons | E2: <16 yrs | F2: 2021/22 | G2: 19.7 | H2: 19.7 | I2: 19.7 | J2: 2063261 | K2: 10467816 | L2: 20210000 | M2: 1y
A3: B01b - Children in absolute low income families (under 16s) | B3: Cheshire West and Chester | C3: Upper tier local authorities (post 4/23) | D3: Persons | E3: <16 yrs | F3: 2021/22 | G3: 15.6 | H3: 15.2 | I3: 16 | J3: 9631 | K3: 61623 | L3: 20210000 | M3: 1y
A4: B01b - Children in absolute low income families (under 16s) | B4: England | C4: England | D4: Persons | E4: <16 yrs | F4: 2022/23 | G4: 21.9 | H4: 21.9 | I4: 21.9 | J4: 2316688 | K4: 10581013 | L4: 20220000 | M4: 1y
A5: B01b - Children in absolute low income families (under 16s) | B5: Cheshire West and Chester | C5: Upper tier local authorities (post 4/23) | D5: Persons | E5: <16 yrs | F5: 2022/23 | G5: 17.8 | H5: 17.3 | I5: 18.2 | J5: 11094 | K5: 62433 | L5: 20220000 | M5: 1y
A6: B01b - Children in absolute low income families (under 16s) | B6: England | C6: England | D6: Persons | E6: <16 yrs | F6: 2023/24 | G6: 21.1 | H6: 21.1 | I6: 21.2 | J6: 2262910 | K6: 10703266 | L6: 20230000 | M6: 1y
A7: B01b - Children in absolute low income families (under 16s) | B7: Cheshire West and Chester | C7: Upper tier local authorities (post 4/23) | D7: Persons | E7: <16 yrs | F7: 2023/24 | G7: 16.7 | H7: 16.3 | I7: 17.1 | J7: 10535 | K7: 63087 | L7: 20230000 | M7: 1y
A8: B01b - Children in absolute low income families (under 16s) | B8: England | C8: England | D8: Persons | E8: <16 yrs | F8: 2024/25 | G8: 19.8 | H8: 19.8 | I8: 19.8 | J8: 2130679 | K8: 10768248 | L8: 20240000 | M8: 1y
A9: B01b - Children in absolute low income families (under 16s) | B9: Cheshire West and Chester | C9: Upper tier local authorities (post 4/23) | D9: Persons | E9: <16 yrs | F9: 2024/25 | G9: 15.1 | H9: 14.7 | I9: 15.5 | J9: 9524 | K9: 63122 | L9: 20240000 | M9: 1y
